Workbook

Sheet Teaser
B2: ='Data Sheet'!B2&" - Company Snapshot" -> TITAN COMPANY LTD - Company Snapshot
C4: HOLD
C5: Target Price: | D5: ='P E Valuation'!H4 -> 5088.2674
C6: CMP: | D6: =B11 -> 5169
C7: Downside %: | D7: ='P E Valuation'!$I$4 -> -0.015618619
C8: Target Period: | D8: ='P E Valuation'!$J$4 -> 12 months
B10: ="NSE: "&Comps_Val!$C$9 -> NSE: TITAN | C10: BSE: 500114
B11: 5169 | C11: (28th August, 2026 - close price)
B12: 52-wk high: ₹5,187.45 | C12: 52-wk low: ₹3,307.35
B14: About the Company:
B15: Titan Company Ltd is among India’s most respected lifestyle companies. It has established leadership positions in the Watches, Jewellery and Eyewear categories led by its trusted brands and differentiated customer experience. It was founded in 1984 as a joint-venture between TATA Group and Tamilnadu Industrial Development Corporation (TIDCO).
B17: Figures in INR Crores
B18: Key Historical Financial Metrics | C18: =HistoricalFS!H3 -> 44651 | D18: =HistoricalFS!I3 -> 45016 | E18: =HistoricalFS!J3 -> 45382 | F18: =HistoricalFS!K3 -> 45747 | G18: =HistoricalFS!L3 -> 46112 | I18: Rapid Growth with Stable Margins
B19: Revenue | C19: =HistoricalFS!H6 -> 28799 | D19: =HistoricalFS!I6 -> 40575 | E19: =HistoricalFS!J6 -> 51084 | F19: =HistoricalFS!K6 -> 60456 | G19: =HistoricalFS!L6 -> 87584
B20: Revenue Growth | C20: =HistoricalFS!H7 -> 0.3305766 | D20: =HistoricalFS!I7 -> 0.40890309 | E20: =HistoricalFS!J7 -> 0.25900185 | F20: =HistoricalFS!K7 -> 0.18346253 | G20: =HistoricalFS!L7 -> 0.44872304
B21: Gross Profit Margin | C21: =HistoricalFS!H13 -> 0.19354839 | D21: =HistoricalFS!I13 -> 0.20406654 | E21: =HistoricalFS!J13 -> 0.18440216 | F21: =HistoricalFS!K13 -> 0.17255525 | G21: =HistoricalFS!L13 -> 0.16125091
B22: EBITDA Margin | C22: =HistoricalFS!H19 -> 0.11611514 | D22: =HistoricalFS!I19 -> 0.12032039 | E22: =HistoricalFS!J19 -> 0.10359408 | F22: =HistoricalFS!K19 -> 0.0941842 | G22: =HistoricalFS!L19 -> 0.095416971
B23: EBIT Margin | C23: ='Ratio Analysis'!H13 -> 0.1022605 | D23: ='Ratio Analysis'!I13 -> 0.10945163 | E23: ='Ratio Analysis'!J13 -> 0.092161929 | F23: ='Ratio Analysis'!K13 -> 0.082721318 | G23: ='Ratio Analysis'!L13 -> 0.085986025
B24: Net Profit Margin | C24: =HistoricalFS!H40 -> 0.076322095 | D24: =HistoricalFS!I40 -> 0.08069008 | E24: =HistoricalFS!J40 -> 0.068436301 | F24: =HistoricalFS!K40 -> 0.055197168 | G24: =HistoricalFS!L40 -> 0.057921538
B25: EPS | C25: =HistoricalFS!H44 -> 24.757828 | D25: =HistoricalFS!I44 -> 36.877675 | E25: =HistoricalFS!J44 -> 39.378238 | F25: =HistoricalFS!K44 -> 37.587294 | G25: =HistoricalFS!L44 -> 57.141248
B26: EPS Growth | C26: =HistoricalFS!H45 -> 1.2566735 | D26: =HistoricalFS!I45 -> 0.48953594 | E26: =HistoricalFS!J45 -> 0.067806964 | F26: =HistoricalFS!K45 -> -0.045480549 | G26: =HistoricalFS!L45 -> 0.52022775
B27: Dividend per Share | C27: =HistoricalFS!H48 -> 7.5185853 | D27: =HistoricalFS!I48 -> 10.02478 | E27: =HistoricalFS!J48 -> 11.027258 | F27: =HistoricalFS!K48 -> 11.027258 | G27: =HistoricalFS!L48 -> 15.037171
B28: DPS Growth | C28: =HistoricalFS!H48/HistoricalFS!G48-1 -> 0.875 | D28: =D27/C27-1 -> 0.33333333 | E28: =E27/D27-1 -> 0.1 | F28: =F27/E27-1 -> 0 | G28: =G27/F27-1 -> 0.36363636
B30: Key Financial Ratios | C30: =C18 -> 44651 | D30: =D18 -> 45016 | E30: =E18 -> 45382 | F30: =F18 -> 45747 | G30: =G18 -> 46112 | I30: Share Price - 5Y
B31: Price to Earnings | C31: ='Ratio Analysis'!H27 -> 102.43831 | D31: ='Ratio Analysis'!I27 -> 68.195731 | E31: ='Ratio Analysis'!J27 -> 96.545711 | F31: ='Ratio Analysis'!K27 -> 81.499614 | G31: ='Ratio Analysis'!L27 -> 69.151447
B32: EV/EBITDA | C32: ='Ratio Analysis'!H28 -> 69.037499 | D32: ='Ratio Analysis'!I28 -> 47.377473 | E32: ='Ratio Analysis'!J28 -> 66.425889 | F32: ='Ratio Analysis'!K28 -> 51.134038 | G32: ='Ratio Analysis'!L28 -> 45.412145
B33: EV/Sales | C33: ='Ratio Analysis'!H29 -> 8.0162991 | D33: ='Ratio Analysis'!I29 -> 5.7004762 | E33: ='Ratio Analysis'!J29 -> 6.8813289 | F33: ='Ratio Analysis'!K29 -> 4.8160185 | G33: ='Ratio Analysis'!L29 -> 4.3330893
B34: Price to Book Value | C34: ='Ratio Analysis'!H30 -> 24.20288 | D34: ='Ratio Analysis'!I30 -> 18.839998 | E34: ='Ratio Analysis'!J30 -> 35.933547 | F34: ='Ratio Analysis'!K30 -> 23.396784 | G34: ='Ratio Analysis'!L30 -> 22.340017
B35: Return on Equity | C35: ='Ratio Analysis'!H23 -> 0.23626787 | D35: ='Ratio Analysis'!I23 -> 0.27626361 | E35: ='Ratio Analysis'!J23 -> 0.37219206 | F35: ='Ratio Analysis'!K23 -> 0.28707846 | G35: ='Ratio Analysis'!L23 -> 0.32305929
B36: Return on Capital Employed | C36: ='Ratio Analysis'!H21 -> 0.17764507 | D36: ='Ratio Analysis'!I21 -> 0.20930342 | E36: ='Ratio Analysis'!J21 -> 0.18891698 | F36: ='Ratio Analysis'!K21 -> 0.15434709 | G36: ='Ratio Analysis'!L21 -> 0.16257232
B38: Estimates | C38: ='P E Valuation'!D11 -> 46112 | D38: ='P E Valuation'!E11 -> 46477 | E38: ='P E Valuation'!F11 -> 46842
B39: Revenue | C39: ='P E Valuation'!D13 -> 87584 | D39: ='P E Valuation'!E13 -> 100721.6 | E39: ='P E Valuation'!F13 -> 115829.84
B40: ='P E Valuation'!B16 -> EBITDA | C40: ='P E Valuation'!D16 -> 8357 | D40: ='P E Valuation'!E16 -> 10072.16 | E40: ='P E Valuation'!F16 -> 11582.984
B41: ='DCF - Exit Multiple'!B4 -> EBIT | C41: ='DCF - Exit Multiple'!D4 -> 7981 | D41: ='DCF - Exit Multiple'!E4 -> 9178.15 | E41: ='DCF - Exit Multiple'!F4 -> 10554.872
B42: ='P E Valuation'!B19 -> Net Profit | C42: ='P E Valuation'!D19 -> 5073 | D42: ='P E Valuation'!E19 -> 6043.296 | E42: ='P E Valuation'!F19 -> 6949.7904
B43: ='P E Valuation'!B24 -> EPS | C43: ='P E Valuation'!D24 -> 57.141248 | D43: ='P E Valuation'!E24 -> 68.070466 | E43: ='P E Valuation'!F24 -> 78.281036
B45: Valuation | C45: Implied Value / Share
B46: P/E Valuation | C46: ='P E Valuation'!H4 -> 5088.2674
B47: DCF - Exit Multiple | C47: ='DCF - Exit Multiple'!C34 -> 4211.4835
B48: Probability weighted Scenario | C48: ='Scenario Analysis'!N6 -> 5141.0627
...

Sheet Financials>

Sheet HistoricalFS
B2: ="Historical Financial Statement - "&'Data Sheet'!B2 -> Historical Financial Statement - TITAN COMPANY LTD
B3: Years | C3: ='Data Sheet'!B17 -> 42825 | D3: ='Data Sheet'!C17 -> 43190 | E3: ='Data Sheet'!D17 -> 43555 | F3: ='Data Sheet'!E17 -> 43921 | G3: ='Data Sheet'!F17 -> 44286 | H3: ='Data Sheet'!G17 -> 44651 | I3: ='Data Sheet'!H17 -> 45016 | J3: ='Data Sheet'!I17 -> 45382 | ... L3: ='Data Sheet'!K17 -> 46112
A5: # | B5: Income statement
B6: Sales | C6: =IFERROR('Data Sheet'!B18,0) -> 13260.83 | D6: =IFERROR('Data Sheet'!C18,0) -> 16119.77 | E6: =IFERROR('Data Sheet'!D18,0) -> 19778.52 | F6: =IFERROR('Data Sheet'!E18,0) -> 21052 | G6: =IFERROR('Data Sheet'!F18,0) -> 21644 | H6: =IFERROR('Data Sheet'!G18,0) -> 28799 | I6: =IFERROR('Data Sheet'!H18,0) -> 40575 | J6: =IFERROR('Data Sheet'!I18,0) -> 51084 | ... L6: =IFERROR('Data Sheet'!K18,0) -> 87584
B7: Sales Growth | C7: - | D7: =IFERROR((D6/C6)-1,0) -> 0.21559284 | E7: =IFERROR((E6/D6)-1,0) -> 0.22697284 | F7: =IFERROR((F6/E6)-1,0) -> 0.064387022 | G7: =IFERROR((G6/F6)-1,0) -> 0.028120844 | H7: =IFERROR((H6/G6)-1,0) -> 0.3305766 | I7: =IFERROR((I6/H6)-1,0) -> 0.40890309 | J7: =IFERROR((J6/I6)-1,0) -> 0.25900185 | K7: =IFERROR((K6/J6)-1,0) -> 0.18346253 | L7: =IFERROR((L6/K6)-1,0) -> 0.44872304
B9: COGS | C9: =IFERROR(SUM('Data Sheet'!B19,'Data Sheet'!B21:B23)-1*'Data Sheet'!B20,0) -> 10606.01 | D9: =IFERROR(SUM('Data Sheet'!C19,'Data Sheet'!C21:C23)-1*'Data Sheet'!C20,0) -> 12762.63 | E9: =IFERROR(SUM('Data Sheet'!D19,'Data Sheet'!D21:D23)-1*'Data Sheet'!D20,0) -> 15660.48 | F9: =IFERROR(SUM('Data Sheet'!E19,'Data Sheet'!E21:E23)-1*'Data Sheet'!E20,0) -> 16626 | G9: =IFERROR(SUM('Data Sheet'!F19,'Data Sheet'!F21:F23)-1*'Data Sheet'!F20,0) -> 17661 | H9: =IFERROR(SUM('Data Sheet'!G19,'Data Sheet'!G21:G23)-1*'Data Sheet'!G20,0) -> 23225 | I9: =IFERROR(SUM('Data Sheet'!H19,'Data Sheet'!H21:H23)-1*'Data Sheet'!H20,0) -> 32295 | J9: =IFERROR(SUM('Data Sheet'!I19,'Data Sheet'!I21:I23)-1*'Data Sheet'!I20,0) -> 41664 | ... L9: =IFERROR(SUM('Data Sheet'!K19,'Data Sheet'!K21:K23)-1*'Data Sheet'!K20,0) -> 73461
B10: COGS as % of sales | C10: =IFERROR(C9/C6,0) -> 0.79979986 | D10: =IFERROR(D9/D6,0) -> 0.79173772 | E10: =IFERROR(E9/E6,0) -> 0.79179231 | F10: =IFERROR(F9/F6,0) -> 0.78975869 | G10: =IFERROR(G9/G6,0) -> 0.81597671 | H10: =IFERROR(H9/H6,0) -> 0.80645161 | I10: =IFERROR(I9/I6,0) -> 0.79593346 | J10: =IFERROR(J9/J6,0) -> 0.81559784 | ... L10: =IFERROR(L9/L6,0) -> 0.83874909
B12: Gross Profit | C12: =IFERROR(C6-C9,0) -> 2654.82 | D12: =IFERROR(D6-D9,0) -> 3357.14 | E12: =IFERROR(E6-E9,0) -> 4118.04 | F12: =IFERROR(F6-F9,0) -> 4426 | G12: =IFERROR(G6-G9,0) -> 3983 | H12: =IFERROR(H6-H9,0) -> 5574 | I12: =IFERROR(I6-I9,0) -> 8280 | J12: =IFERROR(J6-J9,0) -> 9420 | ... L12: =IFERROR(L6-L9,0) -> 14123
B13: Gross Margin | C13: =IFERROR(C12/C6,0) -> 0.20020014 | D13: =IFERROR(D12/D6,0) -> 0.20826228 | E13: =IFERROR(E12/E6,0) -> 0.20820769 | F13: =IFERROR(F12/F6,0) -> 0.21024131 | G13: =IFERROR(G12/G6,0) -> 0.18402329 | H13: =IFERROR(H12/H6,0) -> 0.19354839 | I13: =IFERROR(I12/I6,0) -> 0.20406654 | J13: =IFERROR(J12/J6,0) -> 0.18440216 | ... L13: =IFERROR(L12/L6,0) -> 0.16125091
B15: SG&A Expenses | C15: =IFERROR(SUM('Data Sheet'!B24:B25),0) -> 1490.92 | D15: =IFERROR(SUM('Data Sheet'!C24:C25),0) -> 1712.94 | E15: =IFERROR(SUM('Data Sheet'!D24:D25),0) -> 2124.25 | F15: =IFERROR(SUM('Data Sheet'!E24:E25),0) -> 1963 | G15: =IFERROR(SUM('Data Sheet'!F24:F25),0) -> 2258 | H15: =IFERROR(SUM('Data Sheet'!G24:G25),0) -> 2230 | I15: =IFERROR(SUM('Data Sheet'!H24:H25),0) -> 3398 | J15: =IFERROR(SUM('Data Sheet'!I24:I25),0) -> 4128 | ... L15: =IFERROR(SUM('Data Sheet'!K24:K25),0) -> 5766
B16: SG&A Expenses as % of sales | C16: =IFERROR(C15/C6,0) -> 0.11243037 | D16: =IFERROR(D15/D6,0) -> 0.1062633 | E16: =IFERROR(E15/E6,0) -> 0.10740187 | F16: =IFERROR(F15/F6,0) -> 0.093245297 | G16: =IFERROR(G15/G6,0) -> 0.10432452 | H16: =IFERROR(H15/H6,0) -> 0.077433244 | I16: =IFERROR(I15/I6,0) -> 0.083746149 | J16: =IFERROR(J15/J6,0) -> 0.080808081 | ... L16: =IFERROR(L15/L6,0) -> 0.065833942
B18: EBITDA | C18: =C12-C15 -> 1163.9 | D18: =D12-D15 -> 1644.2 | E18: =E12-E15 -> 1993.79 | F18: =F12-F15 -> 2463 | G18: =G12-G15 -> 1725 | H18: =H12-H15 -> 3344 | I18: =I12-I15 -> 4882 | J18: =J12-J15 -> 5292 | ... L18: =L12-L15 -> 8357
B19: EBITDA margin | C19: =IFERROR(C18/C6,0) -> 0.08776977 | D19: =IFERROR(D18/D6,0) -> 0.10199897 | E19: =IFERROR(E18/E6,0) -> 0.10080582 | F19: =IFERROR(F18/F6,0) -> 0.11699601 | G19: =IFERROR(G18/G6,0) -> 0.079698762 | H19: =IFERROR(H18/H6,0) -> 0.11611514 | I19: =IFERROR(I18/I6,0) -> 0.12032039 | J19: =IFERROR(J18/J6,0) -> 0.10359408 | ... L19: =IFERROR(L18/L6,0) -> 0.095416971
B21: Interest | C21: =IFERROR('Data Sheet'!B28,0) -> 37.74 | D21: =IFERROR('Data Sheet'!C28,0) -> 52.92 | E21: =IFERROR('Data Sheet'!D28,0) -> 52.54 | F21: =IFERROR('Data Sheet'!E28,0) -> 166 | G21: =IFERROR('Data Sheet'!F28,0) -> 203 | H21: =IFERROR('Data Sheet'!G28,0) -> 218 | I21: =IFERROR('Data Sheet'!H28,0) -> 300 | J21: =IFERROR('Data Sheet'!I28,0) -> 619 | ... L21: =IFERROR('Data Sheet'!K28,0) -> 1180
B22: Interest as % of sales | C22: =IFERROR(C21/C6,0) -> 0.0028459757 | D22: =IFERROR(D21/D6,0) -> 0.0032829253 | E22: =IFERROR(E21/E6,0) -> 0.0026564172 | F22: =IFERROR(F21/F6,0) -> 0.0078852366 | G22: =IFERROR(G21/G6,0) -> 0.0093790427 | H22: =IFERROR(H21/H6,0) -> 0.0075697073 | I22: =IFERROR(I21/I6,0) -> 0.0073937153 | J22: =IFERROR(J21/J6,0) -> 0.012117297 | ... L22: =IFERROR(L21/L6,0) -> 0.01347278
B24: Depreciation | C24: =IFERROR('Data Sheet'!B27,0) -> 110.53 | D24: =IFERROR('Data Sheet'!C27,0) -> 131.43 | E24: =IFERROR('Data Sheet'!D27,0) -> 162.84 | F24: =IFERROR('Data Sheet'!E27,0) -> 348 | G24: =IFERROR('Data Sheet'!F27,0) -> 375 | H24: =IFERROR('Data Sheet'!G27,0) -> 399 | I24: =IFERROR('Data Sheet'!H27,0) -> 441 | J24: =IFERROR('Data Sheet'!I27,0) -> 584 | ... L24: =IFERROR('Data Sheet'!K27,0) -> 826
B25: Depreciation as % of sales | C25: =IFERROR(C24/C6,0) -> 0.008335074 | D25: =IFERROR(D24/D6,0) -> 0.0081533421 | E25: =IFERROR(E24/E6,0) -> 0.0082331742 | F25: =IFERROR(F24/F6,0) -> 0.016530496 | G25: =IFERROR(G24/G6,0) -> 0.017325818 | H25: =IFERROR(H24/H6,0) -> 0.013854648 | I25: =IFERROR(I24/I6,0) -> 0.010868762 | J25: =IFERROR(J24/J6,0) -> 0.011432151 | ... L25: =IFERROR(L24/L6,0) -> 0.0094309463
B27: EBIT | C27: =C18-C24 -> 1053.37 | D27: =D18-D24 -> 1512.77 | E27: =E18-E24 -> 1830.95 | F27: =F18-F24 -> 2115 | G27: =G18-G24 -> 1350 | H27: =H18-H24 -> 2945 | I27: =I18-I24 -> 4441 | J27: =J18-J24 -> 4708 | ... L27: =L18-L24 -> 7531
B28: EBIT as % of sales | C28: =C27/C6 -> 0.079434696 | D28: =D27/D6 -> 0.093845632 | E28: =E27/E6 -> 0.09257265 | F28: =F27/F6 -> 0.10046551 | G28: =G27/G6 -> 0.062372944 | H28: =H27/H6 -> 0.1022605 | I28: =I27/I6 -> 0.10945163 | J28: =J27/J6 -> 0.092161929 | ... L28: =L27/L6 -> 0.085986025
B30: Other Income | C30: ='Data Sheet'!B26 -> -42.38 | D30: ='Data Sheet'!C26 -> 69.93 | E30: ='Data Sheet'!D26 -> 178.48 | F30: ='Data Sheet'!E26 -> 153 | G30: ='Data Sheet'!F26 -> 180 | H30: ='Data Sheet'!G26 -> 177 | I30: ='Data Sheet'!H26 -> 306 | J30: ='Data Sheet'!I26 -> 534 | ... L30: ='Data Sheet'!K26 -> 450
B31: Other Income as % of sales | C31: =C30/C6 -> -0.0031958784 | D31: =D30/D6 -> 0.0043381512 | E31: =E30/E6 -> 0.009023931 | F31: =F30/F6 -> 0.007267718 | G31: =G30/G6 -> 0.0083163925 | H31: =H30/H6 -> 0.0061460467 | I31: =I30/I6 -> 0.0075415896 | J31: =J30/J6 -> 0.010453371 | ... L31: =L30/L6 -> 0.0051379247
B33: EBT | C33: =IFERROR(C27+C30-C21,0) -> 973.25 | D33: =IFERROR(D27+D30-D21,0) -> 1529.78 | E33: =IFERROR(E27+E30-E21,0) -> 1956.89 | F33: =IFERROR(F27+F30-F21,0) -> 2102 | G33: =IFERROR(G27+G30-G21,0) -> 1327 | H33: =IFERROR(H27+H30-H21,0) -> 2904 | I33: =IFERROR(I27+I30-I21,0) -> 4447 | J33: =IFERROR(J27+J30-J21,0) -> 4623 | ... L33: =IFERROR(L27+L30-L21,0) -> 6801
B34: EBT Margin | C34: =IFERROR(C33/C6,0) -> 0.073392842 | D34: =IFERROR(D33/D6,0) -> 0.094900858 | E34: =IFERROR(E33/E6,0) -> 0.098940163 | F34: =IFERROR(F33/F6,0) -> 0.099847995 | G34: =IFERROR(G33/G6,0) -> 0.061310294 | H34: =IFERROR(H33/H6,0) -> 0.10083683 | I34: =IFERROR(I33/I6,0) -> 0.10959951 | J34: =IFERROR(J33/J6,0) -> 0.090498003 | ... L34: =IFERROR(L33/L6,0) -> 0.077651169
B36: Tax | C36: =IFERROR('Data Sheet'!B30,0) -> 275.97 | D36: =IFERROR('Data Sheet'!C30,0) -> 427.87 | E36: =IFERROR('Data Sheet'!D30,0) -> 568.24 | F36: =IFERROR('Data Sheet'!E30,0) -> 609 | G36: =IFERROR('Data Sheet'!F30,0) -> 353 | H36: =IFERROR('Data Sheet'!G30,0) -> 706 | I36: =IFERROR('Data Sheet'!H30,0) -> 1173 | J36: =IFERROR('Data Sheet'!I30,0) -> 1127 | ... L36: =IFERROR('Data Sheet'!K30,0) -> 1728
B37: Effective Tax rate | C37: =IFERROR(C36/C33,0) -> 0.2835551 | D37: =IFERROR(D36/D33,0) -> 0.27969381 | E37: =IFERROR(E36/E33,0) -> 0.29037912 | F37: =IFERROR(F36/F33,0) -> 0.28972407 | G37: =IFERROR(G36/G33,0) -> 0.26601356 | H37: =IFERROR(H36/H33,0) -> 0.24311295 | I37: =IFERROR(I36/I33,0) -> 0.26377333 | J37: =IFERROR(J36/J33,0) -> 0.24378109 | ... L37: =IFERROR(L36/L33,0) -> 0.25408028
B39: Net Profit | C39: =IFERROR(C33-C36,0) -> 697.28 | D39: =IFERROR(D33-D36,0) -> 1101.91 | E39: =IFERROR(E33-E36,0) -> 1388.65 | F39: =IFERROR(F33-F36,0) -> 1493 | G39: =IFERROR(G33-G36,0) -> 974 | H39: =IFERROR(H33-H36,0) -> 2198 | I39: =IFERROR(I33-I36,0) -> 3274 | J39: =IFERROR(J33-J36,0) -> 3496 | ... L39: =IFERROR(L33-L36,0) -> 5073
B40: Net Profit Margin | C40: =IFERROR(C39/C6,0) -> 0.052581927 | D40: =IFERROR(D39/D6,0) -> 0.068357675 | E40: =IFERROR(E39/E6,0) -> 0.070210006 | F40: =IFERROR(F39/F6,0) -> 0.070919628 | G40: =IFERROR(G39/G6,0) -> 0.045000924 | H40: =IFERROR(H39/H6,0) -> 0.076322095 | I40: =IFERROR(I39/I6,0) -> 0.08069008 | J40: =IFERROR(J39/J6,0) -> 0.068436301 | ... L40: =IFERROR(L39/L6,0) -> 0.057921538
B42: Equity shares outstanding | C42: =IFERROR('Data Sheet'!B96,0) -> 88.78 | D42: =IFERROR('Data Sheet'!C96,0) -> 88.78 | E42: =IFERROR('Data Sheet'!D96,0) -> 88.78 | F42: =IFERROR('Data Sheet'!E96,0) -> 88.78 | G42: =IFERROR('Data Sheet'!F96,0) -> 88.78 | H42: =IFERROR('Data Sheet'!G96,0) -> 88.78 | I42: =IFERROR('Data Sheet'!H96,0) -> 88.78 | J42: =IFERROR('Data Sheet'!I96,0) -> 88.78 | ... L42: =IFERROR('Data Sheet'!K96,0) -> 88.78
B44: EPS | C44: =IFERROR((C39/C42),0) -> 7.8540212 | D44: =IFERROR((D39/D42),0) -> 12.411692 | E44: =IFERROR((E39/E42),0) -> 15.641473 | F44: =IFERROR((F39/F42),0) -> 16.816851 | G44: =IFERROR((G39/G42),0) -> 10.970939 | H44: =IFERROR((H39/H42),0) -> 24.757828 | I44: =IFERROR((I39/I42),0) -> 36.877675 | J44: =IFERROR((J39/J42),0) -> 39.378238 | ... L44: =IFERROR((L39/L42),0) -> 57.141248
B45: EPS Growth % | C45: - | D45: =IFERROR((D44/C44)-1,0) -> 0.58029773 | E45: =IFERROR((E44/D44)-1,0) -> 0.26022089 | F45: =IFERROR((F44/E44)-1,0) -> 0.075144925 | G45: =IFERROR((G44/F44)-1,0) -> -0.34762224 | H45: =IFERROR((H44/G44)-1,0) -> 1.2566735 | I45: =IFERROR((I44/H44)-1,0) -> 0.48953594 | J45: =IFERROR((J44/I44)-1,0) -> 0.067806964 | K45: =IFERROR((K44/J44)-1,0) -> -0.045480549 | L45: =IFERROR((L44/K44)-1,0) -> 0.52022775
B47: Dividend | C47: =IFERROR('Data Sheet'!B32,0) -> 230.83 | D47: =IFERROR('Data Sheet'!C32,0) -> 332.92 | E47: =IFERROR('Data Sheet'!D32,0) -> 443.9 | F47: =IFERROR('Data Sheet'!E32,0) -> 356 | G47: =IFERROR('Data Sheet'!F32,0) -> 356 | H47: =IFERROR('Data Sheet'!G32,0) -> 667.5 | I47: =IFERROR('Data Sheet'!H32,0) -> 890 | J47: =IFERROR('Data Sheet'!I32,0) -> 979 | ... L47: =IFERROR('Data Sheet'!K32,0) -> 1335
B48: Dividend per share | C48: =IFERROR((C47/C42),0) -> 2.6000225 | D48: =IFERROR((D47/D42),0) -> 3.7499437 | E48: =IFERROR((E47/E42),0) -> 5 | F48: =IFERROR((F47/F42),0) -> 4.0099121 | G48: =IFERROR((G47/G42),0) -> 4.0099121 | H48: =IFERROR((H47/H42),0) -> 7.5185853 | I48: =IFERROR((I47/I42),0) -> 10.02478 | J48: =IFERROR((J47/J42),0) -> 11.027258 | ... L48: =IFERROR((L47/L42),0) -> 15.037171
B49: Divident payout ratio | C49: =IFERROR((C48/C44),0) -> 0.33104348 | D49: =IFERROR((D48/D44),0) -> 0.30212994 | E49: =IFERROR((E48/E44),0) -> 0.31966298 | F49: =IFERROR((F48/F44),0) -> 0.23844608 | G49: =IFERROR((G48/G44),0) -> 0.36550308 | H49: =IFERROR((H48/H44),0) -> 0.30368517 | I49: =IFERROR((I48/I44),0) -> 0.27183873 | J49: =IFERROR((J48/J44),0) -> 0.28003432 | ... L49: =IFERROR((L48/L44),0) -> 0.26315789
B51: Retained earnings | C51: =IFERROR(IF(C44>C48,1-C49,0),0) -> 0.66895652 | D51: =IFERROR(IF(D44>D48,1-D49,0),0) -> 0.69787006 | E51: =IFERROR(IF(E44>E48,1-E49,0),0) -> 0.68033702 | F51: =IFERROR(IF(F44>F48,1-F49,0),0) -> 0.76155392 | G51: =IFERROR(IF(G44>G48,1-G49,0),0) -> 0.63449692 | H51: =IFERROR(IF(H44>H48,1-H49,0),0) -> 0.69631483 | I51: =IFERROR(IF(I44>I48,1-I49,0),0) -> 0.72816127 | J51: =IFERROR(IF(J44>J48,1-J49,0),0) -> 0.71996568 | ... L51: =IFERROR(IF(L44>L48,1-L49,0),0) -> 0.73684211
A53: # | B53: Balance Sheet
B54: Equity Share Capital | C54: =IFERROR('Data Sheet'!B58,0) -> 88.78 | D54: =IFERROR('Data Sheet'!C58,0) -> 88.78 | E54: =IFERROR('Data Sheet'!D58,0) -> 88.78 | F54: =IFERROR('Data Sheet'!E58,0) -> 89 | G54: =IFERROR('Data Sheet'!F58,0) -> 89 | H54: =IFERROR('Data Sheet'!G58,0) -> 89 | I54: =IFERROR('Data Sheet'!H58,0) -> 89 | J54: =IFERROR('Data Sheet'!I58,0) -> 89 | ... L54: =IFERROR('Data Sheet'!K58,0) -> 89
B55: Reserves | C55: =IFERROR('Data Sheet'!B59,0) -> 4143.6 | D55: =IFERROR('Data Sheet'!C59,0) -> 5001.1 | E55: =IFERROR('Data Sheet'!D59,0) -> 5981.37 | F55: =IFERROR('Data Sheet'!E59,0) -> 6580 | G55: =IFERROR('Data Sheet'!F59,0) -> 7408 | H55: =IFERROR('Data Sheet'!G59,0) -> 9214 | I55: =IFERROR('Data Sheet'!H59,0) -> 11762 | J55: =IFERROR('Data Sheet'!I59,0) -> 9304 | ... L55: =IFERROR('Data Sheet'!K59,0) -> 15614
B56: Borrowings | C56: =IFERROR('Data Sheet'!B60,0) -> 1882.43 | D56: =IFERROR('Data Sheet'!C60,0) -> 1691.01 | E56: =IFERROR('Data Sheet'!D60,0) -> 2392.98 | F56: =IFERROR('Data Sheet'!E60,0) -> 3562 | G56: =IFERROR('Data Sheet'!F60,0) -> 5638 | H56: =IFERROR('Data Sheet'!G60,0) -> 7275 | I56: =IFERROR('Data Sheet'!H60,0) -> 9367 | J56: =IFERROR('Data Sheet'!I60,0) -> 15528 | ... L56: =IFERROR('Data Sheet'!K60,0) -> 30621
B57: Other Liabilities | C57: =IFERROR('Data Sheet'!B61,0) -> 2292.76 | D57: =IFERROR('Data Sheet'!C61,0) -> 2740.15 | E57: =IFERROR('Data Sheet'!D61,0) -> 3246.71 | F57: =IFERROR('Data Sheet'!E61,0) -> 3313 | G57: =IFERROR('Data Sheet'!F61,0) -> 3309 | H57: =IFERROR('Data Sheet'!G61,0) -> 4610 | I57: =IFERROR('Data Sheet'!H61,0) -> 5802 | J57: =IFERROR('Data Sheet'!I61,0) -> 6626 | ... L57: =IFERROR('Data Sheet'!K61,0) -> 14237
B58: Total Liabilities | C58: =IFERROR('Data Sheet'!B63,0) -> 8407.57 | D58: =IFERROR('Data Sheet'!C63,0) -> 9521.04 | E58: =IFERROR('Data Sheet'!D63,0) -> 11709.84 | F58: =IFERROR('Data Sheet'!E63,0) -> 13544 | G58: =IFERROR('Data Sheet'!F63,0) -> 16444 | H58: =IFERROR('Data Sheet'!G63,0) -> 21188 | I58: =IFERROR('Data Sheet'!H63,0) -> 27020 | J58: =IFERROR('Data Sheet'!I63,0) -> 31547 | ... L58: =IFERROR('Data Sheet'!K63,0) -> 60561
...

Sheet Ratio Analysis
B2: ="Ratio Analysis - "&'Data Sheet'!B2 -> Ratio Analysis - TITAN COMPANY LTD
B3: Years | C3: ='Data Sheet'!B17 -> 42825 | D3: ='Data Sheet'!C17 -> 43190 | E3: ='Data Sheet'!D17 -> 43555 | F3: ='Data Sheet'!E17 -> 43921 | G3: ='Data Sheet'!F17 -> 44286 | H3: ='Data Sheet'!G17 -> 44651 | I3: ='Data Sheet'!H17 -> 45016 | J3: ='Data Sheet'!I17 -> 45382 | ... L3: ='Data Sheet'!K17 -> 46112 | M3: Trend | N3: Mean | O3: Median
B5: SalesGrowth | D5: =IFERROR(HistoricalFS!D7,0) -> 0.21559284 | E5: =IFERROR(HistoricalFS!E7,0) -> 0.22697284 | F5: =IFERROR(HistoricalFS!F7,0) -> 0.064387022 | G5: =IFERROR(HistoricalFS!G7,0) -> 0.028120844 | H5: =IFERROR(HistoricalFS!H7,0) -> 0.3305766 | I5: =IFERROR(HistoricalFS!I7,0) -> 0.40890309 | J5: =IFERROR(HistoricalFS!J7,0) -> 0.25900185 | K5: =IFERROR(HistoricalFS!K7,0) -> 0.18346253 | L5: =IFERROR(HistoricalFS!L7,0) -> 0.44872304 | N5: =IFERROR(AVERAGE(D5:L5),0) -> 0.24063785 | O5: =IFERROR(MEDIAN(C5:L5),0) -> 0.22697284
B6: EBITDA Growth | D6: =IFERROR((HistoricalFS!D18/HistoricalFS!C18)-1,0) -> 0.41266432 | E6: =IFERROR((HistoricalFS!E18/HistoricalFS!D18)-1,0) -> 0.21262012 | F6: =IFERROR((HistoricalFS!F18/HistoricalFS!E18)-1,0) -> 0.23533572 | G6: =IFERROR((HistoricalFS!G18/HistoricalFS!F18)-1,0) -> -0.29963459 | H6: =IFERROR((HistoricalFS!H18/HistoricalFS!G18)-1,0) -> 0.93855072 | I6: =IFERROR((HistoricalFS!I18/HistoricalFS!H18)-1,0) -> 0.45992823 | J6: =IFERROR((HistoricalFS!J18/HistoricalFS!I18)-1,0) -> 0.083981975 | K6: =IFERROR((HistoricalFS!K18/HistoricalFS!J18)-1,0) -> 0.075963719 | L6: =IFERROR((HistoricalFS!L18/HistoricalFS!K18)-1,0) -> 0.46768528 | N6: =IFERROR(AVERAGE(D6:L6),0) -> 0.28745505 | O6: =IFERROR(MEDIAN(C6:L6),0) -> 0.23533572
B7: EBT Growth | D7: =IFERROR((HistoricalFS!D33/HistoricalFS!C33)-1,0) -> 0.57182635 | E7: =IFERROR((HistoricalFS!E33/HistoricalFS!D33)-1,0) -> 0.27919701 | F7: =IFERROR((HistoricalFS!F33/HistoricalFS!E33)-1,0) -> 0.074153376 | G7: =IFERROR((HistoricalFS!G33/HistoricalFS!F33)-1,0) -> -0.36869648 | H7: =IFERROR((HistoricalFS!H33/HistoricalFS!G33)-1,0) -> 1.1883949 | I7: =IFERROR((HistoricalFS!I33/HistoricalFS!H33)-1,0) -> 0.53133609 | J7: =IFERROR((HistoricalFS!J33/HistoricalFS!I33)-1,0) -> 0.039577243 | K7: =IFERROR((HistoricalFS!K33/HistoricalFS!J33)-1,0) -> -0.019035258 | L7: =IFERROR((HistoricalFS!L33/HistoricalFS!K33)-1,0) -> 0.49966924 | N7: =IFERROR(AVERAGE(D7:L7),0) -> 0.31071361 | O7: =IFERROR(MEDIAN(C7:L7),0) -> 0.27919701
B8: Net Profit Growth | D8: =IFERROR((HistoricalFS!D39/HistoricalFS!C39)-1,0) -> 0.58029773 | E8: =IFERROR((HistoricalFS!E39/HistoricalFS!D39)-1,0) -> 0.26022089 | F8: =IFERROR((HistoricalFS!F39/HistoricalFS!E39)-1,0) -> 0.075144925 | G8: =IFERROR((HistoricalFS!G39/HistoricalFS!F39)-1,0) -> -0.34762224 | H8: =IFERROR((HistoricalFS!H39/HistoricalFS!G39)-1,0) -> 1.2566735 | I8: =IFERROR((HistoricalFS!I39/HistoricalFS!H39)-1,0) -> 0.48953594 | J8: =IFERROR((HistoricalFS!J39/HistoricalFS!I39)-1,0) -> 0.067806964 | K8: =IFERROR((HistoricalFS!K39/HistoricalFS!J39)-1,0) -> -0.045480549 | L8: =IFERROR((HistoricalFS!L39/HistoricalFS!K39)-1,0) -> 0.52022775 | N8: =IFERROR(AVERAGE(D8:L8),0) -> 0.31742277 | O8: =IFERROR(MEDIAN(C8:L8),0) -> 0.26022089
B9: Dividend per share Growth | D9: =IFERROR((HistoricalFS!D48/HistoricalFS!C48)-1,0) -> 0.44227353 | E9: =IFERROR((HistoricalFS!E48/HistoricalFS!D48)-1,0) -> 0.33335336 | F9: =IFERROR((HistoricalFS!F48/HistoricalFS!E48)-1,0) -> -0.19801757 | G9: =IFERROR((HistoricalFS!G48/HistoricalFS!F48)-1,0) -> 0 | H9: =IFERROR((HistoricalFS!H48/HistoricalFS!G48)-1,0) -> 0.875 | I9: =IFERROR((HistoricalFS!I48/HistoricalFS!H48)-1,0) -> 0.33333333 | J9: =IFERROR((HistoricalFS!J48/HistoricalFS!I48)-1,0) -> 0.1 | K9: =IFERROR((HistoricalFS!K48/HistoricalFS!J48)-1,0) -> 0 | L9: =IFERROR((HistoricalFS!L48/HistoricalFS!K48)-1,0) -> 0.36363636 | N9: =IFERROR(AVERAGE(D9:L9),0) -> 0.24995322 | O9: =IFERROR(MEDIAN(C9:L9),0) -> 0.33333333
B11: Gross Margin | C11: =IFERROR(HistoricalFS!C13,0) -> 0.20020014 | D11: =IFERROR(HistoricalFS!D13,0) -> 0.20826228 | E11: =IFERROR(HistoricalFS!E13,0) -> 0.20820769 | F11: =IFERROR(HistoricalFS!F13,0) -> 0.21024131 | G11: =IFERROR(HistoricalFS!G13,0) -> 0.18402329 | H11: =IFERROR(HistoricalFS!H13,0) -> 0.19354839 | I11: =IFERROR(HistoricalFS!I13,0) -> 0.20406654 | J11: =IFERROR(HistoricalFS!J13,0) -> 0.18440216 | ... L11: =IFERROR(HistoricalFS!L13,0) -> 0.16125091 | N11: =IFERROR(AVERAGE(C11:L11),0) -> 0.1926758 | O11: =IFERROR(MEDIAN(C11:L11),0) -> 0.19687426
B12: EBITDA Margin | C12: =IFERROR(HistoricalFS!C19,0) -> 0.08776977 | D12: =IFERROR(HistoricalFS!D19,0) -> 0.10199897 | E12: =IFERROR(HistoricalFS!E19,0) -> 0.10080582 | F12: =IFERROR(HistoricalFS!F19,0) -> 0.11699601 | G12: =IFERROR(HistoricalFS!G19,0) -> 0.079698762 | H12: =IFERROR(HistoricalFS!H19,0) -> 0.11611514 | I12: =IFERROR(HistoricalFS!I19,0) -> 0.12032039 | J12: =IFERROR(HistoricalFS!J19,0) -> 0.10359408 | ... L12: =IFERROR(HistoricalFS!L19,0) -> 0.095416971 | N12: =IFERROR(AVERAGE(C12:L12),0) -> 0.10169001 | O12: =IFERROR(MEDIAN(C12:L12),0) -> 0.1014024
B13: EBIT Margin | C13: =IFERROR(((HistoricalFS!C18-HistoricalFS!C24)/HistoricalFS!C6),0) -> 0.079434696 | D13: =IFERROR(((HistoricalFS!D18-HistoricalFS!D24)/HistoricalFS!D6),0) -> 0.093845632 | E13: =IFERROR(((HistoricalFS!E18-HistoricalFS!E24)/HistoricalFS!E6),0) -> 0.09257265 | F13: =IFERROR(((HistoricalFS!F18-HistoricalFS!F24)/HistoricalFS!F6),0) -> 0.10046551 | G13: =IFERROR(((HistoricalFS!G18-HistoricalFS!G24)/HistoricalFS!G6),0) -> 0.062372944 | H13: =IFERROR(((HistoricalFS!H18-HistoricalFS!H24)/HistoricalFS!H6),0) -> 0.1022605 | I13: =IFERROR(((HistoricalFS!I18-HistoricalFS!I24)/HistoricalFS!I6),0) -> 0.10945163 | J13: =IFERROR(((HistoricalFS!J18-HistoricalFS!J24)/HistoricalFS!J6),0) -> 0.092161929 | ... L13: =IFERROR(((HistoricalFS!L18-HistoricalFS!L24)/HistoricalFS!L6),0) -> 0.085986025 | N13: =IFERROR(AVERAGE(C13:L13),0) -> 0.090127284 | O13: =IFERROR(MEDIAN(C13:L13),0) -> 0.092367289
B14: EBT Margin | C14: =IFERROR(HistoricalFS!C34,0) -> 0.073392842 | D14: =IFERROR(HistoricalFS!D34,0) -> 0.094900858 | E14: =IFERROR(HistoricalFS!E34,0) -> 0.098940163 | F14: =IFERROR(HistoricalFS!F34,0) -> 0.099847995 | G14: =IFERROR(HistoricalFS!G34,0) -> 0.061310294 | H14: =IFERROR(HistoricalFS!H34,0) -> 0.10083683 | I14: =IFERROR(HistoricalFS!I34,0) -> 0.10959951 | J14: =IFERROR(HistoricalFS!J34,0) -> 0.090498003 | ... L14: =IFERROR(HistoricalFS!L34,0) -> 0.077651169 | N14: =IFERROR(AVERAGE(C14:L14),0) -> 0.08819909 | O14: =IFERROR(MEDIAN(C14:L14),0) -> 0.092699431
B15: Net Profit Margin | C15: =IFERROR(HistoricalFS!C40,0) -> 0.052581927 | D15: =IFERROR(HistoricalFS!D40,0) -> 0.068357675 | E15: =IFERROR(HistoricalFS!E40,0) -> 0.070210006 | F15: =IFERROR(HistoricalFS!F40,0) -> 0.070919628 | G15: =IFERROR(HistoricalFS!G40,0) -> 0.045000924 | H15: =IFERROR(HistoricalFS!H40,0) -> 0.076322095 | I15: =IFERROR(HistoricalFS!I40,0) -> 0.08069008 | J15: =IFERROR(HistoricalFS!J40,0) -> 0.068436301 | ... L15: =IFERROR(HistoricalFS!L40,0) -> 0.057921538 | N15: =IFERROR(AVERAGE(C15:L15),0) -> 0.064563734 | O15: =IFERROR(MEDIAN(C15:L15),0) -> 0.068396988
B17: SalesExpenses%Sales | C17: =IFERROR(HistoricalFS!C16,0) -> 0.11243037 | D17: =IFERROR(HistoricalFS!D16,0) -> 0.1062633 | E17: =IFERROR(HistoricalFS!E16,0) -> 0.10740187 | F17: =IFERROR(HistoricalFS!F16,0) -> 0.093245297 | G17: =IFERROR(HistoricalFS!G16,0) -> 0.10432452 | H17: =IFERROR(HistoricalFS!H16,0) -> 0.077433244 | I17: =IFERROR(HistoricalFS!I16,0) -> 0.083746149 | J17: =IFERROR(HistoricalFS!J16,0) -> 0.080808081 | ... L17: =IFERROR(HistoricalFS!L16,0) -> 0.065833942 | N17: =IFERROR(AVERAGE(C17:L17),0) -> 0.090985782 | O17: =IFERROR(MEDIAN(C17:L17),0) -> 0.088495723
B18: Depreciation%Sales | C18: =IFERROR(HistoricalFS!C25,0) -> 0.008335074 | D18: =IFERROR(HistoricalFS!D25,0) -> 0.0081533421 | E18: =IFERROR(HistoricalFS!E25,0) -> 0.0082331742 | F18: =IFERROR(HistoricalFS!F25,0) -> 0.016530496 | G18: =IFERROR(HistoricalFS!G25,0) -> 0.017325818 | H18: =IFERROR(HistoricalFS!H25,0) -> 0.013854648 | I18: =IFERROR(HistoricalFS!I25,0) -> 0.010868762 | J18: =IFERROR(HistoricalFS!J25,0) -> 0.011432151 | ... L18: =IFERROR(HistoricalFS!L25,0) -> 0.0094309463 | N18: =IFERROR(AVERAGE(C18:L18),0) -> 0.011562729 | O18: =IFERROR(MEDIAN(C18:L18),0) -> 0.011150456
B19: OperatingIncome%Sales | C19: =C13 -> 0.079434696 | D19: =D13 -> 0.093845632 | E19: =E13 -> 0.09257265 | F19: =F13 -> 0.10046551 | G19: =G13 -> 0.062372944 | H19: =H13 -> 0.1022605 | I19: =I13 -> 0.10945163 | J19: =J13 -> 0.092161929 | ... L19: =L13 -> 0.085986025 | N19: =IFERROR(AVERAGE(C19:L19),0) -> 0.090127284 | O19: =IFERROR(MEDIAN(C19:L19),0) -> 0.092367289
B21: Return on Capital Employed | C21: =IFERROR((HistoricalFS!C18-HistoricalFS!C24)/(SUM(HistoricalFS!C54:C56)),0) -> 0.17226537 | D21: =IFERROR((HistoricalFS!D18-HistoricalFS!D24)/(SUM(HistoricalFS!D54:D56)),0) -> 0.22309313 | E21: =IFERROR((HistoricalFS!E18-HistoricalFS!E24)/(SUM(HistoricalFS!E54:E56)),0) -> 0.21634431 | F21: =IFERROR((HistoricalFS!F18-HistoricalFS!F24)/(SUM(HistoricalFS!F54:F56)),0) -> 0.20672466 | G21: =IFERROR((HistoricalFS!G18-HistoricalFS!G24)/(SUM(HistoricalFS!G54:G56)),0) -> 0.10277884 | H21: =IFERROR((HistoricalFS!H18-HistoricalFS!H24)/(SUM(HistoricalFS!H54:H56)),0) -> 0.17764507 | I21: =IFERROR((HistoricalFS!I18-HistoricalFS!I24)/(SUM(HistoricalFS!I54:I56)),0) -> 0.20930342 | J21: =IFERROR((HistoricalFS!J18-HistoricalFS!J24)/(SUM(HistoricalFS!J54:J56)),0) -> 0.18891698 | ... L21: =IFERROR((HistoricalFS!L18-HistoricalFS!L24)/(SUM(HistoricalFS!L54:L56)),0) -> 0.16257232 | N21: =IFERROR(AVERAGE(C21:L21),0) -> 0.18139912 | O21: =IFERROR(MEDIAN(C21:L21),0) -> 0.18328102
B22: Retained Earnings% | C22: =IFERROR(HistoricalFS!C51,0) -> 0.66895652 | D22: =IFERROR(HistoricalFS!D51,0) -> 0.69787006 | E22: =IFERROR(HistoricalFS!E51,0) -> 0.68033702 | F22: =IFERROR(HistoricalFS!F51,0) -> 0.76155392 | G22: =IFERROR(HistoricalFS!G51,0) -> 0.63449692 | H22: =IFERROR(HistoricalFS!H51,0) -> 0.69631483 | I22: =IFERROR(HistoricalFS!I51,0) -> 0.72816127 | J22: =IFERROR(HistoricalFS!J51,0) -> 0.71996568 | ... L22: =IFERROR(HistoricalFS!L51,0) -> 0.73684211 | N22: =IFERROR(AVERAGE(C22:L22),0) -> 0.7031121 | O22: =IFERROR(MEDIAN(C22:L22),0) -> 0.70224639
B23: Return on Equity% | C23: =IFERROR(HistoricalFS!C39/SUM(HistoricalFS!C54:C55),0) -> 0.16474891 | D23: =IFERROR(HistoricalFS!D39/SUM(HistoricalFS!D54:D55),0) -> 0.21649037 | E23: =IFERROR(HistoricalFS!E39/SUM(HistoricalFS!E54:E55),0) -> 0.228767 | F23: =IFERROR(HistoricalFS!F39/SUM(HistoricalFS!F54:F55),0) -> 0.22387164 | G23: =IFERROR(HistoricalFS!G39/SUM(HistoricalFS!G54:G55),0) -> 0.12991863 | H23: =IFERROR(HistoricalFS!H39/SUM(HistoricalFS!H54:H55),0) -> 0.23626787 | I23: =IFERROR(HistoricalFS!I39/SUM(HistoricalFS!I54:I55),0) -> 0.27626361 | J23: =IFERROR(HistoricalFS!J39/SUM(HistoricalFS!J54:J55),0) -> 0.37219206 | ... L23: =IFERROR(HistoricalFS!L39/SUM(HistoricalFS!L54:L55),0) -> 0.32305929 | N23: =IFERROR(AVERAGE(C23:L23),0) -> 0.24586578 | O23: =IFERROR(MEDIAN(C23:L23),0) -> 0.23251743
B24: Self Sustained Growth Rate | C24: =IFERROR(C22*C23,0) -> 0.11020986 | D24: =IFERROR(D22*D23,0) -> 0.15108215 | E24: =IFERROR(E22*E23,0) -> 0.15563866 | F24: =IFERROR(F22*F23,0) -> 0.17049033 | G24: =IFERROR(G22*G23,0) -> 0.082432973 | H24: =IFERROR(H22*H23,0) -> 0.16451682 | I24: =IFERROR(I22*I23,0) -> 0.20116446 | J24: =IFERROR(J22*J23,0) -> 0.26796551 | ... L24: =IFERROR(L22*L23,0) -> 0.23804369 | N24: =IFERROR(AVERAGE(C24:L24),0) -> 0.17444006 | O24: =IFERROR(MEDIAN(C24:L24),0) -> 0.16750358
B25: Interest Coverage Ratio | C25: =IFERROR((HistoricalFS!C18-HistoricalFS!C24)/HistoricalFS!C21,0) -> 27.911235 | D25: =IFERROR((HistoricalFS!D18-HistoricalFS!D24)/HistoricalFS!D21,0) -> 28.585979 | E25: =IFERROR((HistoricalFS!E18-HistoricalFS!E24)/HistoricalFS!E21,0) -> 34.848687 | F25: =IFERROR((HistoricalFS!F18-HistoricalFS!F24)/HistoricalFS!F21,0) -> 12.740964 | G25: =IFERROR((HistoricalFS!G18-HistoricalFS!G24)/HistoricalFS!G21,0) -> 6.6502463 | H25: =IFERROR((HistoricalFS!H18-HistoricalFS!H24)/HistoricalFS!H21,0) -> 13.509174 | I25: =IFERROR((HistoricalFS!I18-HistoricalFS!I24)/HistoricalFS!I21,0) -> 14.803333 | J25: =IFERROR((HistoricalFS!J18-HistoricalFS!J24)/HistoricalFS!J21,0) -> 7.6058158 | ... L25: =IFERROR((HistoricalFS!L18-HistoricalFS!L24)/HistoricalFS!L21,0) -> 6.3822034 | N25: =IFERROR(AVERAGE(C25:L25),0) -> 15.828528 | O25: =IFERROR(MEDIAN(C25:L25),0) -> 13.125069
B27: Price to Earnings | C27: =IFERROR('Data Sheet'!B92/HistoricalFS!C44,0) -> 58.918863 | D27: =IFERROR('Data Sheet'!C92/HistoricalFS!D44,0) -> 75.920351 | E27: =IFERROR('Data Sheet'!D92/HistoricalFS!E44,0) -> 73.001435 | F27: =IFERROR('Data Sheet'!E92/HistoricalFS!F44,0) -> 55.521692 | G27: =IFERROR('Data Sheet'!F92/HistoricalFS!G44,0) -> 142.0161 | H27: =IFERROR('Data Sheet'!G92/HistoricalFS!H44,0) -> 102.43831 | I27: =IFERROR('Data Sheet'!H92/HistoricalFS!I44,0) -> 68.195731 | J27: =IFERROR('Data Sheet'!I92/HistoricalFS!J44,0) -> 96.545711 | ... L27: =IFERROR('Data Sheet'!K92/HistoricalFS!L44,0) -> 69.151447 | N27: =IFERROR(AVERAGE(C27:L27),0) -> 82.320925 | O27: =IFERROR(MEDIAN(C27:L27),0) -> 74.460893
B28: EV/EBITDA | C28: ='Data Sheet'!B99/HistoricalFS!C18 -> 36.245764 | D28: ='Data Sheet'!C99/HistoricalFS!D18 -> 51.532961 | E28: ='Data Sheet'!D99/HistoricalFS!E18 -> 51.50991 | F28: ='Data Sheet'!E99/HistoricalFS!F18 -> 34.947173 | G28: ='Data Sheet'!F99/HistoricalFS!G18 -> 83.131408 | H28: ='Data Sheet'!G99/HistoricalFS!H18 -> 69.037499 | I28: ='Data Sheet'!H99/HistoricalFS!I18 -> 47.377473 | J28: ='Data Sheet'!I99/HistoricalFS!J18 -> 66.425889 | ... L28: ='Data Sheet'!K99/HistoricalFS!L18 -> 45.412145 | N28: =IFERROR(AVERAGE(C28:L28),0) -> 53.675426 | O28: =IFERROR(MEDIAN(C28:L28),0) -> 51.321974
B29: EV/Sales | C29: ='Data Sheet'!B99/HistoricalFS!C6 -> 3.1812824 | D29: ='Data Sheet'!C99/HistoricalFS!D6 -> 5.2563091 | E29: ='Data Sheet'!D99/HistoricalFS!E6 -> 5.1924989 | F29: ='Data Sheet'!E99/HistoricalFS!F6 -> 4.0886797 | G29: ='Data Sheet'!F99/HistoricalFS!G6 -> 6.6254703 | H29: ='Data Sheet'!G99/HistoricalFS!H6 -> 8.0162991 | I29: ='Data Sheet'!H99/HistoricalFS!I6 -> 5.7004762 | J29: ='Data Sheet'!I99/HistoricalFS!J6 -> 6.8813289 | ... L29: ='Data Sheet'!K99/HistoricalFS!L6 -> 4.3330893 | N29: =IFERROR(AVERAGE(C29:L29),0) -> 5.4091452 | O29: =IFERROR(MEDIAN(C29:L29),0) -> 5.224404
B30: Price to Book Value | C30: ='Data Sheet'!B98/'Data Sheet'!B100 -> 9.7068186 | D30: ='Data Sheet'!C98/'Data Sheet'!C100 -> 16.436025 | E30: ='Data Sheet'!D98/'Data Sheet'!D100 -> 16.700319 | F30: ='Data Sheet'!E98/'Data Sheet'!E100 -> 12.429732 | G30: ='Data Sheet'!F98/'Data Sheet'!F100 -> 18.450537 | H30: ='Data Sheet'!G98/'Data Sheet'!G100 -> 24.20288 | I30: ='Data Sheet'!H98/'Data Sheet'!H100 -> 18.839998 | J30: ='Data Sheet'!I98/'Data Sheet'!I100 -> 35.933547 | ... L30: ='Data Sheet'!K98/'Data Sheet'!K100 -> 22.340017 | N30: =IFERROR(AVERAGE(C30:L30),0) -> 19.843666 | O30: =IFERROR(MEDIAN(C30:L30),0) -> 18.645268
B32: Debtor Turnover Ratio | C32: =IFERROR(HistoricalFS!C6/HistoricalFS!C66,0) -> 63.87683 | D32: =IFERROR(HistoricalFS!D6/HistoricalFS!D66,0) -> 54.515777 | E32: =IFERROR(HistoricalFS!E6/HistoricalFS!E66,0) -> 47.041313 | F32: =IFERROR(HistoricalFS!F6/HistoricalFS!F66,0) -> 67.474359 | G32: =IFERROR(HistoricalFS!G6/HistoricalFS!G66,0) -> 59.136612 | H32: =IFERROR(HistoricalFS!H6/HistoricalFS!H66,0) -> 50.971681 | I32: =IFERROR(HistoricalFS!I6/HistoricalFS!I66,0) -> 60.200297 | J32: =IFERROR(HistoricalFS!J6/HistoricalFS!J66,0) -> 50.180747 | ... L32: =IFERROR(HistoricalFS!L6/HistoricalFS!L66,0) -> 95.615721 | N32: =IFERROR(AVERAGE(C32:L32),0) -> 60.562008 | O32: =IFERROR(MEDIAN(C32:L32),0) -> 57.871677
B33: Creditor Turnover Ratio | C33: =IFERROR(HistoricalFS!C6/'Data Sheet'!B62,0) -> 16.935926 | D33: =IFERROR(HistoricalFS!D6/'Data Sheet'!C62,0) -> 18.359647 | E33: =IFERROR(HistoricalFS!E6/'Data Sheet'!D62,0) -> 21.830596 | F33: =IFERROR(HistoricalFS!F6/'Data Sheet'!E62,0) -> 35.322148 | G33: =IFERROR(HistoricalFS!G6/'Data Sheet'!F62,0) -> 27.432193 | H33: =IFERROR(HistoricalFS!H6/'Data Sheet'!G62,0) -> 22.255796 | I33: =IFERROR(HistoricalFS!I6/'Data Sheet'!H62,0) -> 33.42257 | J33: =IFERROR(HistoricalFS!J6/'Data Sheet'!I62,0) -> 36.229787 | ... L33: =IFERROR(HistoricalFS!L6/'Data Sheet'!K62,0) -> 30.581006 | N33: =IFERROR(AVERAGE(C33:L33),0) -> 27.316743 | O33: =IFERROR(MEDIAN(C33:L33),0) -> 29.006599
B34: Inventory Turnover | C34: =IFERROR(HistoricalFS!C9/HistoricalFS!C67,0) -> 2.153181 | D34: =IFERROR(HistoricalFS!D9/HistoricalFS!D67,0) -> 2.1540885 | E34: =IFERROR(HistoricalFS!E9/HistoricalFS!E67,0) -> 2.2248729 | F34: =IFERROR(HistoricalFS!F9/HistoricalFS!F67,0) -> 2.0518327 | G34: =IFERROR(HistoricalFS!G9/HistoricalFS!G67,0) -> 2.1004995 | H34: =IFERROR(HistoricalFS!H9/HistoricalFS!H67,0) -> 1.7065912 | I34: =IFERROR(HistoricalFS!I9/HistoricalFS!I67,0) -> 1.9473589 | J34: =IFERROR(HistoricalFS!J9/HistoricalFS!J67,0) -> 2.1869718 | ... L34: =IFERROR(HistoricalFS!L9/HistoricalFS!L67,0) -> 1.7186674 | N34: =IFERROR(AVERAGE(C34:L34),0) -> 2.0018972 | O34: =IFERROR(MEDIAN(C34:L34),0) -> 2.0761661
B35: Fixed Asset Turnover | C35: =IFERROR(HistoricalFS!C6/HistoricalFS!C60,0) -> 11.155554 | D35: =IFERROR(HistoricalFS!D6/HistoricalFS!D60,0) -> 10.937482 | E35: =IFERROR(HistoricalFS!E6/HistoricalFS!E60,0) -> 12.624883 | F35: =IFERROR(HistoricalFS!F6/HistoricalFS!F60,0) -> 7.9954425 | G35: =IFERROR(HistoricalFS!G6/HistoricalFS!G60,0) -> 8.5786762 | H35: =IFERROR(HistoricalFS!H6/HistoricalFS!H60,0) -> 11.320362 | I35: =IFERROR(HistoricalFS!I6/HistoricalFS!I60,0) -> 13.534023 | J35: =IFERROR(HistoricalFS!J6/HistoricalFS!J60,0) -> 13.772985 | ... L35: =IFERROR(HistoricalFS!L6/HistoricalFS!L60,0) -> 12.733934 | N35: =IFERROR(AVERAGE(C35:L35),0) -> 11.753665 | O35: =IFERROR(MEDIAN(C35:L35),0) -> 11.972622
B36: Capital Turnover Ratio | C36: =IFERROR(HistoricalFS!C6/(SUM(HistoricalFS!C54:C55)),0) -> 3.1331851 | D36: =IFERROR(HistoricalFS!D6/(SUM(HistoricalFS!D54:D55)),0) -> 3.1670236 | E36: =IFERROR(HistoricalFS!E6/(SUM(HistoricalFS!E54:E55)),0) -> 3.2583248 | F36: =IFERROR(HistoricalFS!F6/(SUM(HistoricalFS!F54:F55)),0) -> 3.1566952 | G36: =IFERROR(HistoricalFS!G6/(SUM(HistoricalFS!G54:G55)),0) -> 2.8870215 | H36: =IFERROR(HistoricalFS!H6/(SUM(HistoricalFS!H54:H55)),0) -> 3.0956681 | I36: =IFERROR(HistoricalFS!I6/(SUM(HistoricalFS!I54:I55)),0) -> 3.4237617 | J36: =IFERROR(HistoricalFS!J6/(SUM(HistoricalFS!J54:J55)),0) -> 5.438518 | ... L36: =IFERROR(HistoricalFS!L6/(SUM(HistoricalFS!L54:L55)),0) -> 5.577533 | N36: =IFERROR(AVERAGE(C36:L36),0) -> 3.8338694 | O36: =IFERROR(MEDIAN(C36:L36),0) -> 3.2126742
B38: (in days)
B39: Debtor Days | C39: =IFERROR(365/C32,0) -> 5.714122 | D39: =IFERROR(365/D32,0) -> 6.6953095 | E39: =IFERROR(365/E32,0) -> 7.7591372 | F39: =IFERROR(365/F32,0) -> 5.4094623 | G39: =IFERROR(365/G32,0) -> 6.1721493 | H39: =IFERROR(365/H32,0) -> 7.1608389 | I39: =IFERROR(365/I32,0) -> 6.063093 | J39: =IFERROR(365/J32,0) -> 7.2737061 | ... L39: =IFERROR(365/L32,0) -> 3.8173639 | N39: =IFERROR(AVERAGE(C39:L39),0) -> 6.2513177 | O39: =IFERROR(MEDIAN(C39:L39),0) -> 6.3100723
B40: Payable Days | C40: =IFERROR(365/C33,0) -> 21.551818 | D40: =IFERROR(365/D33,0) -> 19.880557 | E40: =IFERROR(365/E33,0) -> 16.719653 | F40: =IFERROR(365/F33,0) -> 10.33346 | G40: =IFERROR(365/G33,0) -> 13.305535 | H40: =IFERROR(365/H33,0) -> 16.400222 | I40: =IFERROR(365/I33,0) -> 10.920764 | J40: =IFERROR(365/J33,0) -> 10.074583 | ... L40: =IFERROR(365/L33,0) -> 11.935513 | N40: =IFERROR(AVERAGE(C40:L40),0) -> 14.297362 | O40: =IFERROR(MEDIAN(C40:L40),0) -> 12.620524
B41: Inventory Days | C41: =IFERROR(365/C34,0) -> 169.51663 | D41: =IFERROR(365/D34,0) -> 169.44522 | E41: =IFERROR(365/E34,0) -> 164.05431 | F41: =IFERROR(365/F34,0) -> 177.88975 | G41: =IFERROR(365/G34,0) -> 173.76819 | H41: =IFERROR(365/H34,0) -> 213.87664 | I41: =IFERROR(365/I34,0) -> 187.43335 | J41: =IFERROR(365/J34,0) -> 166.89744 | ... L41: =IFERROR(365/L34,0) -> 212.37384 | N41: =IFERROR(AVERAGE(C41:L41),0) -> 184.08999 | O41: =IFERROR(MEDIAN(C41:L41),0) -> 175.82897
B42: Cash Conversion Cycle (in days) | C42: =IFERROR(SUM(C39,C41)-C40,0) -> 153.67894 | D42: =IFERROR(SUM(D39,D41)-D40,0) -> 156.25997 | E42: =IFERROR(SUM(E39,E41)-E40,0) -> 155.0938 | F42: =IFERROR(SUM(F39,F41)-F40,0) -> 172.96575 | G42: =IFERROR(SUM(G39,G41)-G40,0) -> 166.6348 | H42: =IFERROR(SUM(H39,H41)-H40,0) -> 204.63726 | I42: =IFERROR(SUM(I39,I41)-I40,0) -> 182.57568 | J42: =IFERROR(SUM(J39,J41)-J40,0) -> 164.09656 | ... L42: =IFERROR(SUM(L39,L41)-L40,0) -> 204.2557 | N42: =IFERROR(AVERAGE(C42:L42),0) -> 176.04394 | O42: =IFERROR(MEDIAN(C42:L42),0) -> 169.80028
B44: CFO/Sales | C44: =IFERROR(HistoricalFS!C83/HistoricalFS!C6,0) -> 0.14063976 | D44: =IFERROR(HistoricalFS!D83/HistoricalFS!D6,0) -> -0.06309023 | E44: =IFERROR(HistoricalFS!E83/HistoricalFS!E6,0) -> 0.01001086 | F44: =IFERROR(HistoricalFS!F83/HistoricalFS!F6,0) -> -0.087972639 | G44: =IFERROR(HistoricalFS!G83/HistoricalFS!G6,0) -> 0.19104602 | H44: =IFERROR(HistoricalFS!H83/HistoricalFS!H6,0) -> -0.17820063 | I44: =IFERROR(HistoricalFS!I83/HistoricalFS!I6,0) -> -0.023265558 | J44: =IFERROR(HistoricalFS!J83/HistoricalFS!J6,0) -> -0.017285256 | ... L44: =IFERROR(HistoricalFS!L83/HistoricalFS!L6,0) -> -0.032357508 | N44: =IFERROR(AVERAGE(C44:L44),0) -> -0.019668995 | O44: =IFERROR(MEDIAN(C44:L44),0) -> -0.027811533
B45: CFO/Total Assets | C45: =IFERROR(HistoricalFS!C83/HistoricalFS!C71,0) -> 0.2218239 | D45: =IFERROR(HistoricalFS!D83/HistoricalFS!D71,0) -> -0.10681606 | E45: =IFERROR(HistoricalFS!E83/HistoricalFS!E71,0) -> 0.016908856 | F45: =IFERROR(HistoricalFS!F83/HistoricalFS!F71,0) -> -0.13673952 | G45: =IFERROR(HistoricalFS!G83/HistoricalFS!G71,0) -> 0.2514595 | H45: =IFERROR(HistoricalFS!H83/HistoricalFS!H71,0) -> -0.24221257 | I45: =IFERROR(HistoricalFS!I83/HistoricalFS!I71,0) -> -0.034937084 | J45: =IFERROR(HistoricalFS!J83/HistoricalFS!J71,0) -> -0.027989983 | ... L45: =IFERROR(HistoricalFS!L83/HistoricalFS!L71,0) -> -0.046795793 | N45: =IFERROR(AVERAGE(C45:L45),0) -> -0.03079067 | O45: =IFERROR(MEDIAN(C45:L45),0) -> -0.040866438
B46: CFO/Total Debt | C46: =IFERROR(HistoricalFS!C83/HistoricalFS!C56,0) -> 0.99074069 | D46: =IFERROR(HistoricalFS!D83/HistoricalFS!D56,0) -> -0.60141572 | E46: =IFERROR(HistoricalFS!E83/HistoricalFS!E56,0) -> 0.08274202 | F46: =IFERROR(HistoricalFS!F83/HistoricalFS!F56,0) -> -0.51993262 | G46: =IFERROR(HistoricalFS!G83/HistoricalFS!G56,0) -> 0.73341611 | H46: =IFERROR(HistoricalFS!H83/HistoricalFS!H56,0) -> -0.70542955 | I46: =IFERROR(HistoricalFS!I83/HistoricalFS!I56,0) -> -0.10077933 | J46: =IFERROR(HistoricalFS!J83/HistoricalFS!J56,0) -> -0.056865018 | ... L46: =IFERROR(HistoricalFS!L83/HistoricalFS!L56,0) -> -0.092550864 | N46: =IFERROR(AVERAGE(C46:L46),0) -> -0.066642603 | O46: =IFERROR(MEDIAN(C46:L46),0) -> -0.096665098

Sheet Common Size Statement
B3: ="Common Size Income Statement - "&'Data Sheet'!$B$2 -> Common Size Income Statement - TITAN COMPANY LTD
B5: Particulars | C5: ='Data Sheet'!B$17 -> 42825 | D5: ='Data Sheet'!C$17 -> 43190 | E5: ='Data Sheet'!D$17 -> 43555 | F5: ='Data Sheet'!E$17 -> 43921 | G5: ='Data Sheet'!F$17 -> 44286 | H5: ='Data Sheet'!G$17 -> 44651 | I5: ='Data Sheet'!H$17 -> 45016 | J5: ='Data Sheet'!I$17 -> 45382 | ... L5: ='Data Sheet'!K$17 -> 46112
B7: ='Data Sheet'!A18 -> Sales | C7: ='Data Sheet'!B18/'Data Sheet'!B$18 -> 1 | D7: ='Data Sheet'!C18/'Data Sheet'!C$18 -> 1 | E7: ='Data Sheet'!D18/'Data Sheet'!D$18 -> 1 | F7: ='Data Sheet'!E18/'Data Sheet'!E$18 -> 1 | G7: ='Data Sheet'!F18/'Data Sheet'!F$18 -> 1 | H7: ='Data Sheet'!G18/'Data Sheet'!G$18 -> 1 | I7: ='Data Sheet'!H18/'Data Sheet'!H$18 -> 1 | J7: ='Data Sheet'!I18/'Data Sheet'!I$18 -> 1 | ... L7: ='Data Sheet'!K18/'Data Sheet'!K$18 -> 1
B8: ='Data Sheet'!A19 -> Raw Material Cost | C8: ='Data Sheet'!B19/'Data Sheet'!B$18 -> 0.74061277 | D8: ='Data Sheet'!C19/'Data Sheet'!C$18 -> 0.78567064 | E8: ='Data Sheet'!D19/'Data Sheet'!D$18 -> 0.76702706 | F8: ='Data Sheet'!E19/'Data Sheet'!E$18 -> 0.76159035 | G8: ='Data Sheet'!F19/'Data Sheet'!F$18 -> 0.75272593 | H8: ='Data Sheet'!G19/'Data Sheet'!G$18 -> 0.91794854 | I8: ='Data Sheet'!H19/'Data Sheet'!H$18 -> 0.8031793 | J8: ='Data Sheet'!I19/'Data Sheet'!I$18 -> 0.82419153 | ... L8: ='Data Sheet'!K19/'Data Sheet'!K$18 -> 0.91618332
B9: ='Data Sheet'!A20 -> Change in Inventory | C9: ='Data Sheet'!B20/'Data Sheet'!B$18 -> 0.02365689 | D9: ='Data Sheet'!C20/'Data Sheet'!C$18 -> 0.060708683 | E9: ='Data Sheet'!D20/'Data Sheet'!D$18 -> 0.039255212 | F9: ='Data Sheet'!E20/'Data Sheet'!E$18 -> 0.041706251 | G9: ='Data Sheet'!F20/'Data Sheet'!F$18 -> -0.0056366661 | H9: ='Data Sheet'!G20/'Data Sheet'!G$18 -> 0.16649884 | I9: ='Data Sheet'!H20/'Data Sheet'!H$18 -> 0.055058534 | J9: ='Data Sheet'!I20/'Data Sheet'!I$18 -> 0.05228643 | ... L9: ='Data Sheet'!K20/'Data Sheet'!K$18 -> 0.11344538
B10: ='Data Sheet'!A21 -> Power and Fuel | C10: ='Data Sheet'!B21/'Data Sheet'!B$18 -> 0.0033059771 | D10: ='Data Sheet'!C21/'Data Sheet'!C$18 -> 0.0028114545 | E10: ='Data Sheet'!D21/'Data Sheet'!D$18 -> 0.0024526608 | F10: ='Data Sheet'!E21/'Data Sheet'!E$18 -> 0.0024700741 | G10: ='Data Sheet'!F21/'Data Sheet'!F$18 -> 0.0017094807 | H10: ='Data Sheet'!G21/'Data Sheet'!G$18 -> 0.0015625543 | I10: ='Data Sheet'!H21/'Data Sheet'!H$18 -> 0.0014540974 | J10: ='Data Sheet'!I21/'Data Sheet'!I$18 -> 0.0013898677 | ... L10: ='Data Sheet'!K21/'Data Sheet'!K$18 -> 0.00099333212
B11: ='Data Sheet'!A22 -> Other Mfr. Exp | C11: ='Data Sheet'!B22/'Data Sheet'!B$18 -> 0.012097282 | D11: ='Data Sheet'!C22/'Data Sheet'!C$18 -> 0.007743907 | E11: ='Data Sheet'!D22/'Data Sheet'!D$18 -> 0.0097722175 | F11: ='Data Sheet'!E22/'Data Sheet'!E$18 -> 0.010212806 | G11: ='Data Sheet'!F22/'Data Sheet'!F$18 -> 0.0065145075 | H11: ='Data Sheet'!G22/'Data Sheet'!G$18 -> 0.0063543873 | I11: ='Data Sheet'!H22/'Data Sheet'!H$18 -> 0.0055452865 | J11: ='Data Sheet'!I22/'Data Sheet'!I$18 -> 0.0055986219 | ... L11: ='Data Sheet'!K22/'Data Sheet'!K$18 -> 0.0042816039
B12: ='Data Sheet'!A23 -> Employee Cost | C12: ='Data Sheet'!B23/'Data Sheet'!B$18 -> 0.067440726 | D12: ='Data Sheet'!C23/'Data Sheet'!C$18 -> 0.056220405 | E12: ='Data Sheet'!D23/'Data Sheet'!D$18 -> 0.051795584 | F12: ='Data Sheet'!E23/'Data Sheet'!E$18 -> 0.057191716 | G12: ='Data Sheet'!F23/'Data Sheet'!F$18 -> 0.049390131 | H12: ='Data Sheet'!G23/'Data Sheet'!G$18 -> 0.047084968 | I12: ='Data Sheet'!H23/'Data Sheet'!H$18 -> 0.040813309 | J12: ='Data Sheet'!I23/'Data Sheet'!I$18 -> 0.036704252 | ... L12: ='Data Sheet'!K23/'Data Sheet'!K$18 -> 0.030736208
B13: ='Data Sheet'!A24 -> Selling and admin | C13: ='Data Sheet'!B24/'Data Sheet'!B$18 -> 0.09133365 | D13: ='Data Sheet'!C24/'Data Sheet'!C$18 -> 0.079269741 | E13: ='Data Sheet'!D24/'Data Sheet'!D$18 -> 0.073530274 | F13: ='Data Sheet'!E24/'Data Sheet'!E$18 -> 0.069827095 | G13: ='Data Sheet'!F24/'Data Sheet'!F$18 -> 0.047542044 | H13: ='Data Sheet'!G24/'Data Sheet'!G$18 -> 0.058925657 | I13: ='Data Sheet'!H24/'Data Sheet'!H$18 -> 0.066913124 | J13: ='Data Sheet'!I24/'Data Sheet'!I$18 -> 0.063601128 | ... L13: ='Data Sheet'!K24/'Data Sheet'!K$18 -> 0.0477827
B14: ='Data Sheet'!A25 -> Other Expenses | C14: ='Data Sheet'!B25/'Data Sheet'!B$18 -> 0.021096719 | D14: ='Data Sheet'!C25/'Data Sheet'!C$18 -> 0.026993561 | E14: ='Data Sheet'!D25/'Data Sheet'!D$18 -> 0.033871594 | F14: ='Data Sheet'!E25/'Data Sheet'!E$18 -> 0.023418203 | G14: ='Data Sheet'!F25/'Data Sheet'!F$18 -> 0.05678248 | H14: ='Data Sheet'!G25/'Data Sheet'!G$18 -> 0.018507587 | I14: ='Data Sheet'!H25/'Data Sheet'!H$18 -> 0.016833025 | J14: ='Data Sheet'!I25/'Data Sheet'!I$18 -> 0.017206953 | ... L14: ='Data Sheet'!K25/'Data Sheet'!K$18 -> 0.018051242
B15: ='Data Sheet'!A26 -> Other Income | C15: ='Data Sheet'!B26/'Data Sheet'!B$18 -> -0.0031958784 | D15: ='Data Sheet'!C26/'Data Sheet'!C$18 -> 0.0043381512 | E15: ='Data Sheet'!D26/'Data Sheet'!D$18 -> 0.009023931 | F15: ='Data Sheet'!E26/'Data Sheet'!E$18 -> 0.007267718 | G15: ='Data Sheet'!F26/'Data Sheet'!F$18 -> 0.0083163925 | H15: ='Data Sheet'!G26/'Data Sheet'!G$18 -> 0.0061460467 | I15: ='Data Sheet'!H26/'Data Sheet'!H$18 -> 0.0075415896 | J15: ='Data Sheet'!I26/'Data Sheet'!I$18 -> 0.010453371 | ... L15: ='Data Sheet'!K26/'Data Sheet'!K$18 -> 0.0051379247
B16: ='Data Sheet'!A27 -> Depreciation | C16: ='Data Sheet'!B27/'Data Sheet'!B$18 -> 0.008335074 | D16: ='Data Sheet'!C27/'Data Sheet'!C$18 -> 0.0081533421 | E16: ='Data Sheet'!D27/'Data Sheet'!D$18 -> 0.0082331742 | F16: ='Data Sheet'!E27/'Data Sheet'!E$18 -> 0.016530496 | G16: ='Data Sheet'!F27/'Data Sheet'!F$18 -> 0.017325818 | H16: ='Data Sheet'!G27/'Data Sheet'!G$18 -> 0.013854648 | I16: ='Data Sheet'!H27/'Data Sheet'!H$18 -> 0.010868762 | J16: ='Data Sheet'!I27/'Data Sheet'!I$18 -> 0.011432151 | ... L16: ='Data Sheet'!K27/'Data Sheet'!K$18 -> 0.0094309463
B17: ='Data Sheet'!A28 -> Interest | C17: ='Data Sheet'!B28/'Data Sheet'!B$18 -> 0.0028459757 | D17: ='Data Sheet'!C28/'Data Sheet'!C$18 -> 0.0032829253 | E17: ='Data Sheet'!D28/'Data Sheet'!D$18 -> 0.0026564172 | F17: ='Data Sheet'!E28/'Data Sheet'!E$18 -> 0.0078852366 | G17: ='Data Sheet'!F28/'Data Sheet'!F$18 -> 0.0093790427 | H17: ='Data Sheet'!G28/'Data Sheet'!G$18 -> 0.0075697073 | I17: ='Data Sheet'!H28/'Data Sheet'!H$18 -> 0.0073937153 | J17: ='Data Sheet'!I28/'Data Sheet'!I$18 -> 0.012117297 | ... L17: ='Data Sheet'!K28/'Data Sheet'!K$18 -> 0.01347278
B18: ='Data Sheet'!A29 -> Profit before tax | C18: ='Data Sheet'!B29/'Data Sheet'!B$18 -> 0.073392842 | D18: ='Data Sheet'!C29/'Data Sheet'!C$18 -> 0.094900858 | E18: ='Data Sheet'!D29/'Data Sheet'!D$18 -> 0.098940163 | F18: ='Data Sheet'!E29/'Data Sheet'!E$18 -> 0.099847995 | G18: ='Data Sheet'!F29/'Data Sheet'!F$18 -> 0.061310294 | H18: ='Data Sheet'!G29/'Data Sheet'!G$18 -> 0.10083683 | I18: ='Data Sheet'!H29/'Data Sheet'!H$18 -> 0.10959951 | J18: ='Data Sheet'!I29/'Data Sheet'!I$18 -> 0.090498003 | ... L18: ='Data Sheet'!K29/'Data Sheet'!K$18 -> 0.077651169
... B21: ='Data Sheet'!A32 -> Dividend Amount | C21: ='Data Sheet'!B32/'Data Sheet'!B$18 -> 0.017406904 | D21: ='Data Sheet'!C32/'Data Sheet'!C$18 -> 0.0206529 | E21: ='Data Sheet'!D32/'Data Sheet'!D$18 -> 0.02244354 | F21: ='Data Sheet'!E32/'Data Sheet'!E$18 -> 0.016910507 | G21: ='Data Sheet'!F32/'Data Sheet'!F$18 -> 0.016447976 | H21: ='Data Sheet'!G32/'Data Sheet'!G$18 -> 0.023177888 | I21: ='Data Sheet'!H32/'Data Sheet'!H$18 -> 0.021934689 | J21: ='Data Sheet'!I32/'Data Sheet'!I$18 -> 0.019164513 | ... L21: ='Data Sheet'!K32/'Data Sheet'!K$18 -> 0.01524251
B22: ='Data Sheet'!A35 -> EBITDA | C22: ='Data Sheet'!B35/'Data Sheet'!B$18 -> 0.08776977 | D22: ='Data Sheet'!C35/'Data Sheet'!C$18 -> 0.10199897 | E22: ='Data Sheet'!D35/'Data Sheet'!D$18 -> 0.10080582 | F22: ='Data Sheet'!E35/'Data Sheet'!E$18 -> 0.11699601 | G22: ='Data Sheet'!F35/'Data Sheet'!F$18 -> 0.079698762 | H22: ='Data Sheet'!G35/'Data Sheet'!G$18 -> 0.11611514 | I22: ='Data Sheet'!H35/'Data Sheet'!H$18 -> 0.12032039 | J22: ='Data Sheet'!I35/'Data Sheet'!I$18 -> 0.10359408 | ... L22: ='Data Sheet'!K35/'Data Sheet'!K$18 -> 0.095416971
B24: ="Common Size Balance Sheet - "&'Data Sheet'!$B$2 -> Common Size Balance Sheet - TITAN COMPANY LTD
B26: Particulars | C26: ='Data Sheet'!B$17 -> 42825 | D26: ='Data Sheet'!C$17 -> 43190 | E26: ='Data Sheet'!D$17 -> 43555 | F26: ='Data Sheet'!E$17 -> 43921 | G26: ='Data Sheet'!F$17 -> 44286 | H26: ='Data Sheet'!G$17 -> 44651 | I26: ='Data Sheet'!H$17 -> 45016 | J26: ='Data Sheet'!I$17 -> 45382 | ... L26: ='Data Sheet'!K$17 -> 46112
B28: Total Liabilities | C28: ='Data Sheet'!B63/'Data Sheet'!B$63 -> 1 | D28: ='Data Sheet'!C63/'Data Sheet'!C$63 -> 1 | E28: ='Data Sheet'!D63/'Data Sheet'!D$63 -> 1 | F28: ='Data Sheet'!E63/'Data Sheet'!E$63 -> 1 | G28: ='Data Sheet'!F63/'Data Sheet'!F$63 -> 1 | H28: ='Data Sheet'!G63/'Data Sheet'!G$63 -> 1 | I28: ='Data Sheet'!H63/'Data Sheet'!H$63 -> 1 | J28: ='Data Sheet'!I63/'Data Sheet'!I$63 -> 1 | ... L28: ='Data Sheet'!K63/'Data Sheet'!K$63 -> 1
B29: ='Data Sheet'!A58 -> Equity Share Capital | C29: ='Data Sheet'!B58/'Data Sheet'!B$63 -> 0.010559531 | D29: ='Data Sheet'!C58/'Data Sheet'!C$63 -> 0.0093246116 | E29: ='Data Sheet'!D58/'Data Sheet'!D$63 -> 0.0075816578 | F29: ='Data Sheet'!E58/'Data Sheet'!E$63 -> 0.0065711754 | G29: ='Data Sheet'!F58/'Data Sheet'!F$63 -> 0.0054123084 | H29: ='Data Sheet'!G58/'Data Sheet'!G$63 -> 0.0042004908 | I29: ='Data Sheet'!H58/'Data Sheet'!H$63 -> 0.0032938564 | J29: ='Data Sheet'!I58/'Data Sheet'!I$63 -> 0.0028211874 | ... L29: ='Data Sheet'!K58/'Data Sheet'!K$63 -> 0.0014695926
B30: ='Data Sheet'!A59 -> Reserves | C30: ='Data Sheet'!B59/'Data Sheet'!B$63 -> 0.49284157 | D30: ='Data Sheet'!C59/'Data Sheet'!C$63 -> 0.52526825 | E30: ='Data Sheet'!D59/'Data Sheet'!D$63 -> 0.51079861 | F30: ='Data Sheet'!E59/'Data Sheet'!E$63 -> 0.48582398 | G30: ='Data Sheet'!F59/'Data Sheet'!F$63 -> 0.45049866 | H30: ='Data Sheet'!G59/'Data Sheet'!G$63 -> 0.43486879 | I30: ='Data Sheet'!H59/'Data Sheet'!H$63 -> 0.43530718 | J30: ='Data Sheet'!I59/'Data Sheet'!I$63 -> 0.29492503 | ... L30: ='Data Sheet'!K59/'Data Sheet'!K$63 -> 0.25782269
B31: ='Data Sheet'!A60 -> Borrowings | C31: ='Data Sheet'!B60/'Data Sheet'!B$63 -> 0.22389704 | D31: ='Data Sheet'!C60/'Data Sheet'!C$63 -> 0.1776077 | E31: ='Data Sheet'!D60/'Data Sheet'!D$63 -> 0.20435634 | F31: ='Data Sheet'!E60/'Data Sheet'!E$63 -> 0.26299468 | G31: ='Data Sheet'!F60/'Data Sheet'!F$63 -> 0.34286062 | H31: ='Data Sheet'!G60/'Data Sheet'!G$63 -> 0.34335473 | I31: ='Data Sheet'!H60/'Data Sheet'!H$63 -> 0.34666913 | J31: ='Data Sheet'!I60/'Data Sheet'!I$63 -> 0.49221796 | ... L31: ='Data Sheet'!K60/'Data Sheet'!K$63 -> 0.50562243
B32: ='Data Sheet'!A61 -> Other Liabilities | C32: ='Data Sheet'!B61/'Data Sheet'!B$63 -> 0.27270186 | D32: ='Data Sheet'!C61/'Data Sheet'!C$63 -> 0.28779944 | E32: ='Data Sheet'!D61/'Data Sheet'!D$63 -> 0.2772634 | F32: ='Data Sheet'!E61/'Data Sheet'!E$63 -> 0.24461016 | G32: ='Data Sheet'!F61/'Data Sheet'!F$63 -> 0.20122841 | H32: ='Data Sheet'!G61/'Data Sheet'!G$63 -> 0.21757599 | I32: ='Data Sheet'!H61/'Data Sheet'!H$63 -> 0.21472983 | J32: ='Data Sheet'!I61/'Data Sheet'!I$63 -> 0.21003582 | ... L32: ='Data Sheet'!K61/'Data Sheet'!K$63 -> 0.23508529
B34: Total Assets | C34: =HistoricalFS!C71/HistoricalFS!C$71 -> 1 | D34: =HistoricalFS!D71/HistoricalFS!D$71 -> 1 | E34: =HistoricalFS!E71/HistoricalFS!E$71 -> 1 | F34: =HistoricalFS!F71/HistoricalFS!F$71 -> 1 | G34: =HistoricalFS!G71/HistoricalFS!G$71 -> 1 | H34: =HistoricalFS!H71/HistoricalFS!H$71 -> 1 | I34: =HistoricalFS!I71/HistoricalFS!I$71 -> 1 | J34: =HistoricalFS!J71/HistoricalFS!J$71 -> 1 | ... L34: =HistoricalFS!L71/HistoricalFS!L$71 -> 1
B35: ='Data Sheet'!A64 -> Net Block | C35: =HistoricalFS!C60/HistoricalFS!C$71 -> 0.14138687 | D35: =HistoricalFS!D60/HistoricalFS!D$71 -> 0.15479506 | E35: =HistoricalFS!E60/HistoricalFS!E$71 -> 0.13378748 | F35: =HistoricalFS!F60/HistoricalFS!F$71 -> 0.19440343 | G35: =HistoricalFS!G60/HistoricalFS!G$71 -> 0.15342982 | H35: =HistoricalFS!H60/HistoricalFS!H$71 -> 0.12006796 | I35: =HistoricalFS!I60/HistoricalFS!I$71 -> 0.11095485 | J35: =HistoricalFS!J60/HistoricalFS!J$71 -> 0.11757061 | ... L35: =HistoricalFS!L60/HistoricalFS!L$71 -> 0.11357144
B36: ='Data Sheet'!A65 -> Capital Work in Progress | C36: =HistoricalFS!C61/HistoricalFS!C$71 -> 0.018087271 | D36: =HistoricalFS!D61/HistoricalFS!D$71 -> 0.0045551746 | E36: =HistoricalFS!E61/HistoricalFS!E$71 -> 0.0027131028 | F36: =HistoricalFS!F61/HistoricalFS!F$71 -> 0.0013290018 | G36: =HistoricalFS!G61/HistoricalFS!G$71 -> 0.0019459985 | H36: =HistoricalFS!H61/HistoricalFS!H$71 -> 0.0040117047 | I36: =HistoricalFS!I61/HistoricalFS!I$71 -> 0.0053293856 | J36: =HistoricalFS!J61/HistoricalFS!J$71 -> 0.0030747773 | ... L36: =HistoricalFS!L61/HistoricalFS!L$71 -> 0.0026915011
B37: ='Data Sheet'!A66 -> Investments | C37: =HistoricalFS!C62/HistoricalFS!C$71 -> 0.051231212 | D37: =HistoricalFS!D62/HistoricalFS!D$71 -> 0.0037800492 | E37: =HistoricalFS!E62/HistoricalFS!E$71 -> 0.0092588797 | F37: =HistoricalFS!F62/HistoricalFS!F$71 -> 0.011665682 | G37: =HistoricalFS!G62/HistoricalFS!G$71 -> 0.17173437 | H37: =HistoricalFS!H62/HistoricalFS!H$71 -> 0.013875779 | I37: =HistoricalFS!I62/HistoricalFS!I$71 -> 0.093079201 | J37: =HistoricalFS!J62/HistoricalFS!J$71 -> 0.074333534 | ... L37: =HistoricalFS!L62/HistoricalFS!L$71 -> 0.057892043
B38: ='Data Sheet'!A67 -> Other Assets | C38: =HistoricalFS!C63/HistoricalFS!C$71 -> 0.086086705 | D38: =HistoricalFS!D63/HistoricalFS!D$71 -> 0.11862465 | E38: =HistoricalFS!E63/HistoricalFS!E$71 -> 0.12615629 | F38: =HistoricalFS!F63/HistoricalFS!F$71 -> 0.14316302 | G38: =HistoricalFS!G63/HistoricalFS!G$71 -> 0.10526636 | H38: =HistoricalFS!H63/HistoricalFS!H$71 -> 0.11884085 | I38: =HistoricalFS!I63/HistoricalFS!I$71 -> 0.10222058 | J38: =HistoricalFS!J63/HistoricalFS!J$71 -> 0.12048689 | ... L38: =HistoricalFS!L63/HistoricalFS!L$71 -> 0.073281485
B39: ='Data Sheet'!A69 -> Receivables | C39: =HistoricalFS!C66/HistoricalFS!C$71 -> 0.024692033 | D39: =HistoricalFS!D66/HistoricalFS!D$71 -> 0.031056481 | E39: =HistoricalFS!E66/HistoricalFS!E$71 -> 0.0359057 | F39: =HistoricalFS!F66/HistoricalFS!F$71 -> 0.023036031 | G39: =HistoricalFS!G66/HistoricalFS!G$71 -> 0.022257358 | H39: =HistoricalFS!H66/HistoricalFS!H$71 -> 0.026666037 | I39: =HistoricalFS!I66/HistoricalFS!I$71 -> 0.024944486 | J39: =HistoricalFS!J66/HistoricalFS!J$71 -> 0.032269312 | ... L39: =HistoricalFS!L66/HistoricalFS!L$71 -> 0.015125246
B40: ='Data Sheet'!A70 -> Inventory | C40: =HistoricalFS!C67/HistoricalFS!C$71 -> 0.58586964 | D40: =HistoricalFS!D67/HistoricalFS!D$71 -> 0.62228916 | E40: =HistoricalFS!E67/HistoricalFS!E$71 -> 0.601103 | F40: =HistoricalFS!F67/HistoricalFS!F$71 -> 0.5982723 | G40: =HistoricalFS!G67/HistoricalFS!G$71 -> 0.51131112 | H40: =HistoricalFS!H67/HistoricalFS!H$71 -> 0.64229753 | I40: =HistoricalFS!I67/HistoricalFS!I$71 -> 0.61376758 | J40: =HistoricalFS!J67/HistoricalFS!J$71 -> 0.6038926 | ... L40: =HistoricalFS!L67/HistoricalFS!L$71 -> 0.70578425
B41: ='Data Sheet'!A71 -> Cash & Bank | C41: =HistoricalFS!C68/HistoricalFS!C$71 -> 0.09264627 | D41: =HistoricalFS!D68/HistoricalFS!D$71 -> 0.064899423 | E41: =HistoricalFS!E68/HistoricalFS!E$71 -> 0.09107554 | F41: =HistoricalFS!F68/HistoricalFS!F$71 -> 0.028130538 | G41: =HistoricalFS!G68/HistoricalFS!G$71 -> 0.034054974 | H41: =HistoricalFS!H68/HistoricalFS!H$71 -> 0.074240136 | I41: =HistoricalFS!I68/HistoricalFS!I$71 -> 0.049703923 | J41: =HistoricalFS!J68/HistoricalFS!J$71 -> 0.04837227 | ... L41: =HistoricalFS!L68/HistoricalFS!L$71 -> 0.031654035

Sheet Dupont Analysis
B2: ='Data Sheet'!B2&" - Dupont Analysis" -> TITAN COMPANY LTD - Dupont Analysis
D4: =HistoricalFS!H3 -> 44651 | E4: =HistoricalFS!I3 -> 45016 | F4: =HistoricalFS!J3 -> 45382 | G4: =HistoricalFS!K3 -> 45747 | H4: =HistoricalFS!L3 -> 46112
